# Missing disconnection event

When using `python-socketio` and `aiohttp>=3.9.0` the `disconnect` event is not triggered.
The issue is generated by this 1 line of code https://github.com/ttsia/aiohttp/commit/70b3536e3eef1627bbb425e71faea2f8ce1c6f9b#diff-5eda97b86ffb5b1e8b797dbacc03e6d75767caada5d09956c1035b5684711965R204
Before the above change, the `_close_code` was set to `None`, now it should return `1000`.


# Reproducing issue

The below two commands will run the same code against different versions of `aiohttp`.


### Working aiohttp < 3.9.0

```shell
make run-working
```
```
docker run -it --rm  --privileged test-image:latest ./code_works.sh
Resolved 16 packages in 263ms
Downloaded 16 packages in 71ms
Installed 16 packages in 12ms
 + aiohttp==3.8.6
 + aiosignal==1.3.1
 + async-timeout==4.0.3
 + attrs==23.2.0
 + bidict==0.23.1
 + charset-normalizer==3.3.2
 + frozenlist==1.4.1
 + h11==0.14.0
 + idna==3.6
 + multidict==6.0.5
 + python-engineio==4.9.0
 + python-socketio==5.11.2
 + simple-websocket==1.0.0
 + tenacity==8.2.3
 + wsproto==1.2.0
 + yarl==1.9.4
Server initialized for aiohttp.
Attempting WebSocket connection to ws://127.0.0.1:8328/socket.io/?transport=websocket&EIO=4
a62jkBwNR-XNm9jjAAAA: Sending packet OPEN data {'sid': 'a62jkBwNR-XNm9jjAAAA', 'upgrades': [], 'pingTimeout': 20000, 'pingInterval': 25000}
a62jkBwNR-XNm9jjAAAA: Received request to upgrade to websocket
a62jkBwNR-XNm9jjAAAA: Upgrade to websocket successful
WebSocket connection accepted with {'sid': 'a62jkBwNR-XNm9jjAAAA', 'upgrades': [], 'pingTimeout': 20000, 'pingInterval': 25000}
Engine.IO connection established
Sending packet MESSAGE data 0{}
a62jkBwNR-XNm9jjAAAA: Received packet MESSAGE data 0{}
a62jkBwNR-XNm9jjAAAA: Sending packet MESSAGE data 0{"sid":"IRs6RcL23OI1tTXcAAAB"}
Received packet MESSAGE data 0{"sid":"IRs6RcL23OI1tTXcAAAB"}
Namespace / is connected
Sending packet MESSAGE data 1
Sending packet CLOSE data None
Engine.IO connection dropped
Write loop: WebSocket connection was closed, aborting
Exiting write loop task
Server sent close packet data None, aborting
Waiting for write loop task to end
Exiting read loop task
disconnect calls: [call('IRs6RcL23OI1tTXcAAAB')]
service task canceled
```

### Fails with aiohttp >= 3.9.0

```shell
make run-failing
```
```
docker run -it --rm --privileged test-image:latest ./code_fails.sh
Resolved 15 packages in 255ms
Downloaded 15 packages in 77ms
Installed 15 packages in 12ms
 + aiohttp==3.9.3
 + aiosignal==1.3.1
 + async-timeout==4.0.3
 + attrs==23.2.0
 + bidict==0.23.1
 + frozenlist==1.4.1
 + h11==0.14.0
 + idna==3.6
 + multidict==6.0.5
 + python-engineio==4.9.0
 + python-socketio==5.11.2
 + simple-websocket==1.0.0
 + tenacity==8.2.3
 + wsproto==1.2.0
 + yarl==1.9.4
Server initialized for aiohttp.
Attempting WebSocket connection to ws://127.0.0.1:8328/socket.io/?transport=websocket&EIO=4
EHk25EfbUIRGDJE9AAAA: Sending packet OPEN data {'sid': 'EHk25EfbUIRGDJE9AAAA', 'upgrades': [], 'pingTimeout': 20000, 'pingInterval': 25000}
EHk25EfbUIRGDJE9AAAA: Received request to upgrade to websocket
EHk25EfbUIRGDJE9AAAA: Upgrade to websocket successful
WebSocket connection accepted with {'sid': 'EHk25EfbUIRGDJE9AAAA', 'upgrades': [], 'pingTimeout': 20000, 'pingInterval': 25000}
Engine.IO connection established
Sending packet MESSAGE data 0{}
EHk25EfbUIRGDJE9AAAA: Received packet MESSAGE data 0{}
EHk25EfbUIRGDJE9AAAA: Sending packet MESSAGE data 0{"sid":"4FyS0Vh2z2NQpb6WAAAB"}
Received packet MESSAGE data 0{"sid":"4FyS0Vh2z2NQpb6WAAAB"}
Namespace / is connected
Sending packet MESSAGE data 1
Sending packet CLOSE data None
Engine.IO connection dropped
Write loop: WebSocket connection was closed, aborting
Exiting write loop task
Server sent close packet data None, aborting
Waiting for write loop task to end
Exiting read loop task
service task canceled
Traceback (most recent call last):
  File "//_test_code.py", line 66, in <module>
    asyncio.run(main())
  File "/usr/local/lib/python3.9/asyncio/runners.py", line 44, in run
    return loop.run_until_complete(main)
  File "/usr/local/lib/python3.9/asyncio/base_events.py", line 647, in run_until_complete
    return future.result()
  File "//_test_code.py", line 57, in main
    async for attempt in AsyncRetrying(
  File "/usr/local/lib/python3.9/site-packages/tenacity/_asyncio.py", line 71, in __anext__
    do = self.iter(retry_state=self._retry_state)
  File "/usr/local/lib/python3.9/site-packages/tenacity/__init__.py", line 325, in iter
    raise retry_exc.reraise()
  File "/usr/local/lib/python3.9/site-packages/tenacity/__init__.py", line 158, in reraise
    raise self.last_attempt.result()
  File "/usr/local/lib/python3.9/concurrent/futures/_base.py", line 439, in result
    return self.__get_result()
  File "/usr/local/lib/python3.9/concurrent/futures/_base.py", line 391, in __get_result
    raise self._exception
  File "//_test_code.py", line 61, in main
    assert len(spy_disconnect.call_args_list) == 1
AssertionError
make: *** [Makefile:10: run-failing] Error 1
```